Workbook

Sheet FAMILY Ancona
A1: ANCONA CENTRO | B1: Column2 | C1: NEGOZIO DI RIFERIMENTO | D1: Column4 | E1: Column5 | F1: SELEZIONARE ESITO DAL MENÙ A TENDINA E | G1: Column7 | H1: Column8 | I1: Column9 | J1: Column10 | K1: Column11 | L1: Column12 | M1: Column13 | N1: Column14 | O1: Column15 | P1: Column16 | Q1: Column17
F2: AGGIUNGERE UN COMMENTO
A3: OPERATORE | B3: DATA | C3: TITOLO | D3: SIM | E3: TELEFONO | F3: DATA DI SCADENZA | G3: ESITO | H3: ESITO BO | I3: NOTE BO | J3: ESITO SUITE
A4: SOFIA BRASCA | B4: 04/11/2025 | C4: ATTIVAZIONE CONVERGENZA FISSO - MOBILE | D4: 8939108640011146615 | E4: 3477127668 | F4: 45995 | G4: INSERITA IN FAMIGLIA | J4: OK | K4: SCADUTA | L4: SCADUTA | M4: NON SCADUTA | O4: TIPOLOGIA | Q4: INSERITA IN FAMIGLIA
A5: SOFIA BRASCA | B5: 10/11/2025 | C5: ATTIVAZIONE CONVERGENZA FISSO - MOBILE | D5: 8939108640011147548 | E5: 3498794712 | F5: 46001 | G5: INSERITA IN FAMIGLIA | J5: OK | K5: SCADUTA | L5: ATTIVITÀ SCADUTA | M5: INSERITA IN FAMIGLIA | O5: SCADUTA | Q5: IN ATTESA DI NORMALIZZAZIONE
A6: SOFIA BRASCA | B6: 12/11/2025 | C6: ATTIVAZIONE CONVERGENZA FISSO - MOBILE | D6: 8939108660014734977 | E6: 3463761338 | F6: 46003 | G6: INSERITA IN FAMIGLIA | J6: OK | K6: SCADUTA | M6: IN ATTESA DI NORMALIZZAZIONE | O6: NON SCADUTA | Q6: NON NORMALIZZABILE
A7: SOFIA BRASCA | B7: 14/11/2025 | C7: ATTIVAZIONE CONVERGENZA FISSO - MOBILE | D7: 8939108660014734522 | E7: 3512475862 | F7: 46011 | G7: IN ATTESA DI NORMALIZZAZIONE | H7: NON NORMALIZZABILE | J7: DA ELIMINARE | K7: SCADUTA | M7: NON NORMALIZZABILE | Q7: MNP OUT
A8: SOFIA BRASCA | B8: 14/11/2025 | C8: ATTIVAZIONE CONVERGENZA FISSO - MOBILE | D8: 8939108660014734274 | E8: 3385335492 | F8: 46005 | G8: INSERITA IN FAMIGLIA | J8: OK | K8: SCADUTA | M8: MNP OUT
A9: GABRIELE MALATESTA | B9: 26/11/2025 | C9: ATTIVAZIONE CONVERGENZA FISSO - MOBILE | D9: 8939108660014734720 | E9: 3425275610 | F9: 46011 | G9: IN ATTESA DI NORMALIZZAZIONE | H9: NON NORMALIZZABILE | J9: DA ELIMINARE | K9: SCADUTA

Sheet MNP Ancona
A1: ANCONA CENTRO | B1: Column2 | C1: NEGOZIO DI RIFERIMENTO | D1: Column4 | E1: Column5 | F1: Column6 | G1: Column7 | H1: SELEZIONARE ESITO DAL MENÙ A TENDINA E | I1: Column9 | J1: Column10 | K1: Column11 | L1: Column12 | M1: Column13 | N1: Column14 | O1: Column15 | P1: Column16 | Q1: Column17 | R1: Column18 | S1: Column19 | T1: Column20 | U1: Column21 | V1: Column22 | W1: Column23
H2: AGGIUNGERE UN COMMENTO
A3: OPERATORE | B3: DATA | C3: TITOLO | D3: SIM | E3: TELEFONO | F3: VIRTUALE | G3: DATA DI SCADENZA MNP | H3: DATA DI SCADENZA T+1 | I3: ESITO MNP | J3: ESITO RINNOVO T+1 | K3: ESITO BO | L3: NOTE BO | M3: ESITO SUITE
A4: ORAZIO CARDILE | B4: 01/11/2025 | C4: ATTIVAZIONE SIM MNP - MASSMARKET | D4: 8939108640011146193 | E4: 3288691547 | F4: SI | G4: 45992 | H4: 46002 | I4: MNP EFFETTUATA | J4: RINNOVO EFFETTUATO | M4: OK | N4: SCADUTA | O4: SCADUTA | P4: SCADUTA | Q4: NON SCADUTA | R4: GESTIONE NON ATTIVA | S4: TIPOLOGIA | T4: NON SCADUTA T1 | U4: MNP EFFETTUATA | V4: ESITO BO
A5: SOFIA BRASCA | B5: 01/11/2025 | C5: ATTIVAZIONE SIM MNP - MASSMARKET | D5: 8939108640011146805 | E5: 3393924889 | F5: SI | G5: 45992 | H5: 46002 | I5: MNP EFFETTUATA | J5: RINNOVO EFFETTUATO | M5: OK | N5: SCADUTA | O5: SCADUTA | P5: ATTIVITÀ SCADUTA | Q5: MNP EFFETTUATA | S5: SCADUTA | T5: RINNOVO EFFETTUATO | U5: IN ATTESA DI NORMALIZZAZIONE | V5: OK
A6: GABRIELE MALATESTA | B6: 03/11/2025 | C6: ATTIVAZIONE SIM MNP - MASSMARKET | D6: 8939108640011145971 | E6: 3896942123 | F6: NO | G6: 45994 | H6: 46004 | I6: MNP EFFETTUATA | J6: RINNOVO EFFETTUATO | M6: OK | N6: SCADUTA | O6: SCADUTA | P6: GESTIONE NON ATTIVA | Q6: IN ATTESA DI NORMALIZZAZIONE | S6: NON SCADUTA | T6: SOTTO CREDITO | U6: NON NORMALIZZABILE | V6: IN ATTESA DI NORMALIZZAZIONE
A7: DIMITRI MAZZOCCANTI | B7: 03/11/2025 | C7: ATTIVAZIONE SIM MNP - MASSMARKET | D7: 8939108640011146383 | E7: 3511222103 | F7: NO | G7: 45994 | H7: 46004 | I7: MNP EFFETTUATA | J7: RINNOVO EFFETTUATO | M7: OK | N7: SCADUTA | O7: SCADUTA | Q7: NON NORMALIZZABILE | S7: GESTIONE NON ATTIVA | T7: MNP OUT | U7: MNP OUT | V7: NON NORMALIZZABILE
A8: ORAZIO CARDILE | B8: 04/11/2025 | C8: SIM SCONTATA - ATTIVAZIONE SIM MNP - CONV. FISSO - MOBILE | D8: 8939108640011147233 | E8: 3936002316 | F8: NO | G8: 45995 | H8: 46005 | I8: MNP OUT | J8: NON NORMALIZZABILE | M8: DA ELIMINARE | N8: SCADUTA | O8: SCADUTA | Q8: MNP OUT | T8: NON NORMALIZZABILE | V8: MNP OUT
A9: ORAZIO CARDILE | B9: 06/11/2025 | C9: SIM SCONTATA - ATTIVAZIONE SIM MNP - CONV. FISSO - MOBILE | D9: 8939108640011147225 | E9: 3508006332 | F9: SI | G9: 45997 | H9: 46007 | I9: NON NORMALIZZABILE | J9: RINNOVO EFFETTUATO | K9: NON NORMALIZZABILE | M9: DA ELIMINARE | N9: SCADUTA | O9: SCADUTA
A10: DIMITRI MAZZOCCANTI | B10: 08/11/2025 | C10: ATTIVAZIONE SIM MNP - MASSMARKET | D10: 8939108660005277093 | E10: 3512608457 | F10: NO | G10: 45999 | H10: 46009 | I10: MNP EFFETTUATA | J10: RINNOVO EFFETTUATO | M10: OK | N10: SCADUTA | O10: SCADUTA
A11: ORAZIO CARDILE | B11: 08/11/2025 | C11: SIM SCONTATA - ATTIVAZIONE SIM MNP - CONV. FISSO - MOBILE | D11: 8939108640011146565 | E11: 3393952131 | F11: NO | G11: 45999 | H11: 46009 | I11: MNP EFFETTUATA | J11: RINNOVO EFFETTUATO | M11: OK | N11: SCADUTA | O11: SCADUTA
A12: ORAZIO CARDILE | B12: 08/11/2025 | C12: SIM SCONTATA - ATTIVAZIONE SIM MNP - CONV. FISSO - MOBILE | D12: 8939108630011265481 | E12: 3402742326 | F12: NO | G12: 45999 | H12: 46009 | I12: MNP EFFETTUATA | J12: RINNOVO EFFETTUATO | M12: OK | N12: SCADUTA | O12: SCADUTA
A13: GABRIELE MALATESTA | B13: 11/11/2025 | C13: ATTIVAZIONE SIM MNP - MASSMARKET | D13: 8939108640011146409 | E13: 3248013841 | F13: NO | G13: 46002 | H13: 46012 | I13: MNP EFFETTUATA | J13: RINNOVO EFFETTUATO | M13: OK | N13: SCADUTA | O13: SCADUTA
A14: SOFIA BRASCA | B14: 14/11/2025 | C14: ATTIVAZIONE SIM MNP - MASSMARKET | D14: 8939108660014734548 | E14: 3341467772 | F14: NO | G14: 46005 | H14: 46015 | I14: MNP EFFETTUATA | J14: RINNOVO EFFETTUATO | M14: OK | N14: SCADUTA | O14: SCADUTA
A15: SOFIA BRASCA | B15: 14/11/2025 | C15: ATTIVAZIONE SIM MNP - MASSMARKET | D15: 8939108660014735131 | E15: 3935711739 | F15: NO | G15: 46005 | H15: 46015 | I15: MNP EFFETTUATA | J15: RINNOVO EFFETTUATO | M15: OK | N15: SCADUTA | O15: SCADUTA
A16: SOFIA BRASCA | B16: 14/11/2025 | C16: ATTIVAZIONE SIM MNP - CONVERGENZA FISSO - MOBILE | D16: 8939108660014734274 | E16: 3385335492 | F16: NO | G16: 46005 | H16: 46015 | I16: MNP EFFETTUATA | J16: RINNOVO EFFETTUATO | M16: OK | N16: SCADUTA | O16: SCADUTA
A17: GABRIELE MALATESTA | B17: 15/11/2025 | C17: ATTIVAZIONE SIM MNP - MASSMARKET | D17: 8939108640011146904 | E17: 3473029316 | F17: SI | G17: 46006 | H17: 46016 | I17: MNP EFFETTUATA | J17: RINNOVO EFFETTUATO | M17: OK | N17: SCADUTA | O17: SCADUTA
A18: GABRIELE MALATESTA | B18: 18/11/2025 | C18: ATTIVAZIONE SIM MNP - MASSMARKET | D18: 8939108640011146128 | E18: 3510761292 | F18: SI | G18: 46006 | H18: 46019 | I18: NON NORMALIZZABILE | J18: RINNOVO EFFETTUATO | K18: NON NORMALIZZABILE | M18: DA ELIMINARE | N18: SCADUTA | O18: SCADUTA
A19: ORAZIO CARDILE | B19: 18/11/2025 | C19: ATTIVAZIONE SIM MNP - MASSMARKET | D19: 8939108640011146391 | E19: 3476998795 | F19: SI | G19: 46006 | H19: 46019 | I19: MNP EFFETTUATA | J19: RINNOVO EFFETTUATO | M19: OK | N19: SCADUTA | O19: SCADUTA
A20: GABRIELE MALATESTA | B20: 18/11/2025 | C20: ATTIVAZIONE SIM MNP - FASTWEB | D20: 8939080000125201628 | E20: 3770859843 | F20: NO | G20: 46006 | H20: 46019 | I20: MNP EFFETTUATA | J20: RINNOVO EFFETTUATO | M20: OK | N20: SCADUTA | O20: SCADUTA
A21: SOFIA BRASCA | B21: 19/11/2025 | C21: ATTIVAZIONE SIM MNP - MASSMARKET | D21: 8939108640011147266 | E21: 3400045897 | F21: SI | G21: 46006 | H21: 46020 | I21: MNP EFFETTUATA | J21: RINNOVO EFFETTUATO | M21: OK | N21: SCADUTA | O21: SCADUTA
A22: SOFIA BRASCA | B22: 20/11/2025 | C22: ATTIVAZIONE SIM MNP - MASSMARKET | D22: 8939108660014735057 | E22: 3331800910 | F22: NO | G22: 46006 | H22: 46021 | I22: MNP EFFETTUATA | J22: RINNOVO EFFETTUATO | M22: OK | N22: SCADUTA | O22: SCADUTA
A23: SOFIA BRASCA | B23: 22/11/2025 | C23: SIM SCONTATA - ATTIVAZIONE SIM MNP - CONV. FISSO - MOBILE | D23: 8939108660014734845 | E23: 3929258698 | F23: NO | G23: 46006 | H23: 46023 | I23: MNP EFFETTUATA | J23: RINNOVO EFFETTUATO | M23: OK | N23: SCADUTA | O23: SCADUTA
A24: ORAZIO CARDILE | B24: 24/11/2025 | C24: SIM SCONTATA - ATTIVAZIONE SIM MNP - CONV. FISSO - MOBILE | D24: 8939010002191099146 | E24: 3476717093 | F24: NO | G24: 46006 | H24: 46025 | I24: MNP EFFETTUATA | J24: RINNOVO EFFETTUATO | M24: OK | N24: SCADUTA | O24: SCADUTA
A25: ORAZIO CARDILE | B25: 25/11/2025 | C25: ATTIVAZIONE SIM MNP - MASSMARKET | D25: 8939108660014734613 | E25: 3921673834 | F25: NO | G25: 46006 | H25: 46026 | I25: MNP EFFETTUATA | J25: RINNOVO EFFETTUATO | M25: OK | N25: SCADUTA | O25: SCADUTA
A26: SOFIA BRASCA | B26: 25/11/2025 | C26: SIM SCONTATA - ATTIVAZIONE SIM MNP - CONV. FISSO - MOBILE | D26: 8939108660014733946 | E26: 3476717093 | F26: NO | G26: 46006 | H26: 46026 | I26: MNP EFFETTUATA | J26: RINNOVO EFFETTUATO | M26: OK | N26: SCADUTA | O26: SCADUTA
A27: ORAZIO CARDILE | B27: 25/11/2025 | C27: SIM SCONTATA - ATTIVAZIONE SIM MNP - CONV. FISSO - MOBILE | D27: 8939108660014734621 | E27: 3483655633 | F27: SI | G27: 46006 | H27: 46026 | I27: MNP EFFETTUATA | J27: RINNOVO EFFETTUATO | M27: OK | N27: SCADUTA | O27: SCADUTA
A28: ORAZIO CARDILE | B28: 27/11/2025 | C28: ATTIVAZIONE SIM MNP - MASSMARKET | D28: 8939108640011147076 | E28: 3466634607 | F28: NO | G28: 46006 | H28: 46027 | I28: MNP EFFETTUATA | J28: RINNOVO EFFETTUATO | M28: OK | N28: SCADUTA | O28: SCADUTA
A29: GABRIELE MALATESTA | B29: 27/11/2025 | C29: SIM SCONTATA - ATTIVAZIONE SIM MNP - CONV. FISSO - MOBILE | D29: 8939108640011146649 | E29: 3519300868 | F29: NO | G29: 46006 | H29: 46027 | I29: MNP EFFETTUATA | J29: RINNOVO EFFETTUATO | M29: OK | N29: SCADUTA | O29: SCADUTA
A30: GABRIELE MALATESTA | B30: 29/11/2025 | C30: ATTIVAZIONE SIM MNP - MASSMARKET | D30: 8939108660014734035 | E30: 3511721608 | F30: SI | G30: 46006 | H30: 46027 | I30: MNP EFFETTUATA | J30: RINNOVO EFFETTUATO | M30: OK | N30: SCADUTA | O30: SCADUTA
A31: GABRIELE MALATESTA | B31: 29/11/2025 | C31: ATTIVAZIONE SIM MNP - MASSMARKET | D31: 8939108640011147373 | E31: 3472668031 | F31: NO | G31: 46006 | H31: 46027 | I31: MNP EFFETTUATA | J31: RINNOVO EFFETTUATO | M31: OK | N31: SCADUTA | O31: SCADUTA

Sheet MNP Campobasso
A1: CAMPOBASSO | B1: Column2 | C1: NEGOZIO DI RIFERIMENTO | D1: Column4 | E1: Column5 | F1: Column6 | G1: Column7 | H1: SELEZIONARE ESITO DAL MENÙ A TENDINA E | I1: Column9 | J1: Column10 | K1: Column11 | L1: Column12 | M1: Column13 | N1: Column14 | O1: Column15 | P1: Column16 | Q1: Column17 | R1: Column18 | S1: Column19 | T1: Column20 | U1: Column21 | V1: Column22 | W1: Column23
H2: AGGIUNGERE UN COMMENTO
A3: OPERATORE | B3: DATA | C3: TITOLO | D3: SIM | E3: TELEFONO | F3: VIRTUALE | G3: DATA DI SCADENZA MNP | H3: DATA DI SCADENZA T+1 | I3: ESITO MNP | J3: ESITO RINNOVO T+1 | K3: ESITO BO | L3: NOTE BO | M3: ESITO SUITE
A4: EMANUELA CAMPAJOLA | B4: 02/11/2025 | C4: ATTIVAZIONE SIM MNP - CONVERGENZA FISSO - MOBILE | D4: 8939108640011191587 | E4: 3701325074 | F4: SI | G4: 45993 | H4: 46003 | I4: MNP EFFETTUATA | J4: RINNOVO EFFETTUATO | M4: OK | N4: SCADUTA | O4: SCADUTA | P4: SCADUTA | Q4: NON SCADUTA | R4: GESTIONE NON ATTIVA | S4: TIPOLOGIA | T4: NON SCADUTA T1 | U4: MNP EFFETTUATA | V4: ESITO BO
A5: PAOLO FLORIO | B5: 03/11/2025 | C5: ATTIVAZIONE SIM MNP - MASSMARKET | D5: 8939108640012881962 | E5: 3515969360 | F5: SI | G5: 45994 | H5: 46004 | I5: MNP EFFETTUATA | J5: RINNOVO EFFETTUATO | M5: OK | N5: SCADUTA | O5: SCADUTA | P5: ATTIVITÀ SCADUTA | Q5: MNP EFFETTUATA | S5: SCADUTA | T5: RINNOVO EFFETTUATO | U5: IN ATTESA DI NORMALIZZAZIONE | V5: OK
A6: EMANUELA CAMPAJOLA | B6: 04/11/2025 | C6: ATTIVAZIONE SIM MNP - MASSMARKET | D6: 8939108640011191553 | E6: 3890228153 | F6: NO | G6: 45995 | H6: 46005 | I6: MNP EFFETTUATA | J6: RINNOVO EFFETTUATO | M6: OK | N6: SCADUTA | O6: SCADUTA | P6: GESTIONE NON ATTIVA | Q6: IN ATTESA DI NORMALIZZAZIONE | S6: NON SCADUTA | T6: SOTTO CREDITO | U6: NON NORMALIZZABILE | V6: IN ATTESA DI NORMALIZZAZIONE
A7: EMANUELA CAMPAJOLA | B7: 04/11/2025 | C7: ATTIVAZIONE SIM MNP - MASSMARKET | D7: 8939108640011191827 | E7: 3880934403 | F7: NO | G7: 45995 | H7: 46005 | I7: MNP EFFETTUATA | J7: RINNOVO EFFETTUATO | M7: OK | N7: SCADUTA | O7: SCADUTA | Q7: NON NORMALIZZABILE | S7: GESTIONE NON ATTIVA | T7: MNP OUT | U7: MNP OUT | V7: NON NORMALIZZABILE
A8: EMANUELA CAMPAJOLA | B8: 05/11/2025 | C8: ATTIVAZIONE SIM MNP - MASSMARKET | D8: 8939108640012881947 | E8: 3408087142 | F8: NO | G8: 45996 | H8: 46006 | I8: MNP EFFETTUATA | J8: RINNOVO EFFETTUATO | M8: OK | N8: SCADUTA | O8: SCADUTA | Q8: MNP OUT | T8: NON NORMALIZZABILE | V8: MNP OUT
A9: FEDERICO CHIARULLO | B9: 06/11/2025 | C9: ATTIVAZIONE SIM MNP - MASSMARKET | D9: 8939108640011191876 | E9: 3488583880 | F9: NO | G9: 45997 | H9: 46007 | I9: MNP EFFETTUATA | J9: RINNOVO EFFETTUATO | M9: OK | N9: SCADUTA | O9: SCADUTA
A10: ARDUINO MASELLI | B10: 06/11/2025 | C10: ATTIVAZIONE SIM MNP - CONVERGENZA FISSO - MOBILE | D10: 8939108640011192171 | E10: 3497712486 | F10: SI | G10: 45997 | H10: 46007 | I10: MNP EFFETTUATA | J10: RINNOVO EFFETTUATO | M10: OK | N10: SCADUTA | O10: SCADUTA
A11: FEDERICO CHIARULLO | B11: 07/11/2025 | C11: ATTIVAZIONE SIM MNP - MASSMARKET | D11: 8939108640012881798 | E11: 3203688187 | F11: SI | G11: 45998 | H11: 46008 | I11: MNP EFFETTUATA | J11: RINNOVO EFFETTUATO | M11: OK | N11: SCADUTA | O11: SCADUTA
A12: FEDERICO CHIARULLO | B12: 11/11/2025 | C12: ATTIVAZIONE SIM MNP - MASSMARKET | D12: 8939108640011192528 | E12: 3401952097 | F12: NO | G12: 46002 | H12: 46012 | I12: MNP EFFETTUATA | J12: RINNOVO EFFETTUATO | M12: OK | N12: SCADUTA | O12: SCADUTA
A13: FEDERICO CHIARULLO | B13: 11/11/2025 | C13: SIM SCONTATA - ATTIVAZIONE SIM MNP - CONV. FISSO - MOBILE | D13: 8939108640012881921 | E13: 3478430425 | F13: NO | G13: 46002 | H13: 46012 | I13: MNP EFFETTUATA | J13: RINNOVO EFFETTUATO | M13: OK | N13: SCADUTA | O13: SCADUTA
A14: FEDERICO CHIARULLO | B14: 11/11/2025 | C14: ATTIVAZIONE SIM MNP - CONVERGENZA FISSO - MOBILE | D14: 8939108640011192494 | E14: 3279807174 | F14: SI | G14: 46002 | H14: 46012 | I14: MNP EFFETTUATA | J14: RINNOVO EFFETTUATO | M14: OK | N14: SCADUTA | O14: SCADUTA
A15: ARDUINO MASELLI | B15: 12/11/2025 | C15: ATTIVAZIONE SIM MNP - MASSMARKET | D15: 8939108640011192510 | E15: 3929836265 | F15: NO | G15: 46003 | H15: 46013 | I15: MNP EFFETTUATA | J15: RINNOVO EFFETTUATO | M15: OK | N15: SCADUTA | O15: SCADUTA
A16: FEDERICO CHIARULLO | B16: 13/11/2025 | C16: ATTIVAZIONE SIM MNP - MASSMARKET | D16: 8939108660014935749 | E16: 3513854942 | F16: NO | G16: 46004 | H16: 46014 | I16: MNP EFFETTUATA | J16: RINNOVO EFFETTUATO | M16: OK | N16: SCADUTA | O16: SCADUTA
A17: EMANUELA CAMPAJOLA | B17: 14/11/2025 | C17: SIM SCONTATA - ATTIVAZIONE SIM MNP - CONV. FISSO - MOBILE | D17: 8939108660014935772 | E17: 3205740240 | F17: NO | G17: 46005 | H17: 46015 | I17: MNP EFFETTUATA | J17: RINNOVO EFFETTUATO | M17: OK | N17: SCADUTA | O17: SCADUTA
A18: EMANUELA CAMPAJOLA | B18: 14/11/2025 | C18: ATTIVAZIONE SIM MNP - YOUNG | D18: 8939108640011191686 | E18: 3714533782 | F18: NO | G18: 46005 | H18: 46015 | I18: MNP EFFETTUATA | J18: RINNOVO EFFETTUATO | M18: OK | N18: SCADUTA | O18: SCADUTA
A19: EMANUELA CAMPAJOLA | B19: 17/11/2025 | C19: ATTIVAZIONE SIM MNP - MASSMARKET | D19: 8939108660014936010 | E19: 3661967381 | F19: SI | G19: 46006 | H19: 46018 | I19: MNP EFFETTUATA | J19: RINNOVO EFFETTUATO | M19: OK | N19: SCADUTA | O19: SCADUTA
A20: ARDUINO MASELLI | B20: 17/11/2025 | C20: ATTIVAZIONE SIM MNP - MASSMARKET | D20: 8939108660014935426 | E20: 3895636049 | F20: NO | G20: 46006 | H20: 46018 | I20: MNP EFFETTUATA | J20: RINNOVO EFFETTUATO | M20: OK | N20: SCADUTA | O20: SCADUTA
... A33: EMANUELA CAMPAJOLA | B33: 30/11/2025 | C33: ATTIVAZIONE SIM MNP - MASSMARKET | D33: 8939108640012882135 | E33: 3518690537 | F33: SI | G33: 46006 | H33: 46027 | I33: MNP EFFETTUATA | J33: RINNOVO EFFETTUATO | M33: OK | N33: SCADUTA | O33: SCADUTA

Sheet FAMILY Campobasso
A1: CAMPOBASSO | B1: Column2 | C1: NEGOZIO DI RIFERIMENTO | D1: Column4 | E1: Column5 | F1: SELEZIONARE ESITO DAL MENÙ A TENDINA E | G1: Column7 | H1: Column8 | I1: Column9 | J1: Column10 | K1: Column11 | L1: Column12 | M1: Column13 | N1: Column14 | O1: Column15 | P1: Column16 | Q1: Column17
F2: AGGIUNGERE UN COMMENTO
A3: OPERATORE | B3: DATA | C3: TITOLO | D3: SIM | E3: TELEFONO | F3: DATA DI SCADENZA | G3: ESITO | H3: ESITO BO | I3: NOTE BO | J3: ESITO SUITE
A4: EMANUELA CAMPAJOLA | B4: 02/11/2025 | C4: ATTIVAZIONE CONVERGENZA FISSO - MOBILE | D4: 8939108640011191587 | E4: 3701325074 | F4: 45993 | G4: INSERITA IN FAMIGLIA | J4: OK | K4: SCADUTA | L4: SCADUTA | M4: NON SCADUTA | O4: TIPOLOGIA | Q4: INSERITA IN FAMIGLIA
A5: ARDUINO MASELLI | B5: 06/11/2025 | C5: ATTIVAZIONE CONVERGENZA FISSO - MOBILE | D5: 8939108640011192171 | E5: 3497712486 | F5: 45997 | G5: INSERITA IN FAMIGLIA | J5: OK | K5: SCADUTA | L5: ATTIVITÀ SCADUTA | M5: INSERITA IN FAMIGLIA | O5: SCADUTA | Q5: IN ATTESA DI NORMALIZZAZIONE
A6: ARDUINO MASELLI | B6: 11/11/2025 | C6: ATTIVAZIONE CONVERGENZA FISSO - MOBILE | D6: 8939108650000920904 | E6: 3452156916 | F6: 46002 | G6: INSERITA IN FAMIGLIA | J6: OK | K6: SCADUTA | M6: IN ATTESA DI NORMALIZZAZIONE | O6: NON SCADUTA | Q6: NON NORMALIZZABILE
A7: FEDERICO CHIARULLO | B7: 11/11/2025 | C7: ATTIVAZIONE CONVERGENZA FISSO - MOBILE | D7: 8939108640011192494 | E7: 3279807174 | F7: 46002 | G7: INSERITA IN FAMIGLIA | J7: OK | K7: SCADUTA | M7: NON NORMALIZZABILE | Q7: MNP OUT
A8: ARDUINO MASELLI | B8: 23/11/2025 | C8: ATTIVAZIONE CONVERGENZA FISSO - MOBILE | D8: 8939108660014935434 | E8: 3475748999 | F8: 46006 | G8: INSERITA IN FAMIGLIA | J8: OK | K8: SCADUTA | M8: MNP OUT
A9: ARDUINO MASELLI | B9: 29/11/2025 | C9: ATTIVAZIONE CONVERGENZA FISSO - MOBILE | D9: 8939108660014935780 | E9: 3713412240 | F9: 46006 | G9: INSERITA IN FAMIGLIA | J9: OK | K9: SCADUTA

Sheet FAMILY Colonnella
A1: VAL VIBRATA | B1: Column2 | C1: NEGOZIO DI RIFERIMENTO | D1: Column4 | E1: Column5 | F1: SELEZIONARE ESITO DAL MENÙ A TENDINA E | G1: Column7 | H1: Column8 | I1: Column9 | J1: Column10 | K1: Column11 | L1: Column12 | M1: Column13 | N1: Column14 | O1: Column15 | P1: Column16 | Q1: Column17
F2: AGGIUNGERE UN COMMENTO
A3: OPERATORE | B3: DATA | C3: TITOLO | D3: SIM | E3: TELEFONO | F3: DATA DI SCADENZA | G3: ESITO | H3: ESITO BO | I3: NOTE BO | J3: ESITO SUITE
A4: ENRICA ANGELUCCI | B4: 01/11/2025 | C4: ATTIVAZIONE CONVERGENZA FISSO - MOBILE | D4: 8939108640012792714 | E4: 3391287319 | F4: 45992 | K4: SCADUTA | L4: SCADUTA | M4: NON SCADUTA | O4: TIPOLOGIA | Q4: INSERITA IN FAMIGLIA
A5: ENRICA ANGELUCCI | B5: 02/11/2025 | C5: ATTIVAZIONE CONVERGENZA FISSO - MOBILE | D5: 8939108640011144933 | E5: 3473567466 | F5: 45993 | K5: SCADUTA | L5: ATTIVITÀ SCADUTA | M5: INSERITA IN FAMIGLIA | O5: SCADUTA | Q5: IN ATTESA DI NORMALIZZAZIONE
A6: ENRICA ANGELUCCI | B6: 03/11/2025 | C6: ATTIVAZIONE CONVERGENZA FISSO - MOBILE | D6: 8939108650003652108 | E6: 3490859404 | F6: 45994 | K6: SCADUTA | M6: IN ATTESA DI NORMALIZZAZIONE | O6: NON SCADUTA | Q6: NON NORMALIZZABILE
A7: ANDREA VERGALITO | B7: 06/11/2025 | C7: ATTIVAZIONE CONVERGENZA FISSO - MOBILE | D7: 8939108640013553966 | E7: 3472924297 | F7: 45997 | K7: SCADUTA | M7: NON NORMALIZZABILE | Q7: MNP OUT
A8: ENRICA ANGELUCCI | B8: 09/11/2025 | C8: ATTIVAZIONE CONVERGENZA FISSO - MOBILE | D8: 8939108650000901268 | E8: 3498414026 | F8: 46000 | K8: SCADUTA | M8: MNP OUT
A9: ANDREA VERGALITO | B9: 10/11/2025 | C9: ATTIVAZIONE CONVERGENZA FISSO - MOBILE | D9: 8939108640011144040 | E9: 3515539921 | F9: 46001 | K9: SCADUTA
A10: ANDREA VERGALITO | B10: 13/11/2025 | C10: ATTIVAZIONE CONVERGENZA FISSO - MOBILE | D10: 8939108660014739349 | E10: 3469467111 | F10: 46004 | K10: SCADUTA
A11: ENRICA ANGELUCCI | B11: 14/11/2025 | C11: ATTIVAZIONE CONVERGENZA FISSO - MOBILE | D11: 8939108660014739323 | E11: 3489174140 | F11: 46005 | K11: SCADUTA
A12: FEDERICA LACARBONARA | B12: 22/11/2025 | C12: ATTIVAZIONE CONVERGENZA FISSO - MOBILE | D12: 8939108660014739414 | E12: 3661576318 | F12: 46006 | K12: SCADUTA
A13: FEDERICA LACARBONARA | B13: 23/11/2025 | C13: ATTIVAZIONE CONVERGENZA FISSO - MOBILE | D13: 8939108660014740131 | E13: 3272493319 | F13: 46006 | K13: SCADUTA
A14: ENRICA ANGELUCCI | B14: 23/11/2025 | C14: ATTIVAZIONE CONVERGENZA FISSO - MOBILE | D14: 8939108660014739984 | E14: 3804549713 | F14: 46006 | K14: SCADUTA
A15: ENRICA ANGELUCCI | B15: 28/11/2025 | C15: ATTIVAZIONE CONVERGENZA FISSO - MOBILE | D15: 8939108660014740164 | E15: 3474560129 | F15: 46006 | K15: SCADUTA
A16: ANDREA VERGALITO | B16: 30/11/2025 | C16: ATTIVAZIONE CONVERGENZA FISSO - MOBILE | D16: 8939108660014739299 | E16: 3515015780 | F16: 46006 | K16: SCADUTA
A17: ENRICA ANGELUCCI | B17: 30/11/2025 | C17: ATTIVAZIONE CONVERGENZA FISSO - MOBILE | D17: 8939108660014739711 | E17: 3474641293 | F17: 46006 | K17: SCADUTA
A18: ANDREA VERGALITO | B18: 30/11/2025 | C18: ATTIVAZIONE CONVERGENZA FISSO - MOBILE | D18: 8939108660014739240 | E18: 3286263005 | F18: 46006 | K18: SCADUTA
A19: ANDREA VERGALITO | B19: 30/11/2025 | C19: ATTIVAZIONE CONVERGENZA FISSO - MOBILE | D19: 8939108660014739752 | E19: 3458955561 | F19: 46006 | K19: SCADUTA

Sheet MNP Colonnella
A1: VAL VIBRATA | B1: Column2 | C1: NEGOZIO DI RIFERIMENTO | D1: Column4 | E1: Column5 | F1: Column6 | G1: Column7 | H1: SELEZIONARE ESITO DAL MENÙ A TENDINA E | I1: Column9 | J1: Column10 | K1: Column11 | L1: Column12 | M1: Column13 | N1: Column14 | O1: Column15 | P1: Column16 | Q1: Column17 | R1: Column18 | S1: Column19 | T1: Column20 | U1: Column21 | V1: Column22 | W1: Column23
H2: AGGIUNGERE UN COMMENTO
A3: OPERATORE | B3: DATA | C3: TITOLO | D3: SIM | E3: TELEFONO | F3: VIRTUALE | G3: DATA DI SCADENZA MNP | H3: DATA DI SCADENZA T+1 | I3: ESITO MNP | J3: ESITO RINNOVO T+1 | K3: ESITO BO | L3: NOTE BO | M3: ESITO SUITE
A4: ENRICA ANGELUCCI | B4: 01/11/2025 | C4: ATTIVAZIONE SIM MNP - MASSMARKET | D4: 8939108640011144859 | E4: 3295690588 | F4: NO | G4: 45992 | H4: 46002 | N4: SCADUTA | O4: SCADUTA | P4: SCADUTA | Q4: NON SCADUTA | R4: GESTIONE NON ATTIVA | S4: TIPOLOGIA | T4: NON SCADUTA T1 | U4: MNP EFFETTUATA | V4: ESITO BO
A5: FEDERICA LACARBONARA | B5: 01/11/2025 | C5: ATTIVAZIONE SIM MNP - MASSMARKET | D5: 8939108640012795915 | E5: 3497813293 | F5: NO | G5: 45992 | H5: 46002 | N5: SCADUTA | O5: SCADUTA | P5: ATTIVITÀ SCADUTA | Q5: MNP EFFETTUATA | S5: SCADUTA | T5: RINNOVO EFFETTUATO | U5: IN ATTESA DI NORMALIZZAZIONE | V5: OK
A6: ENRICA ANGELUCCI | B6: 01/11/2025 | C6: ATTIVAZIONE SIM MNP - CONVERGENZA FISSO - MOBILE | D6: 8939108640012792714 | E6: 3391287319 | F6: NO | G6: 45992 | H6: 46002 | N6: SCADUTA | O6: SCADUTA | P6: GESTIONE NON ATTIVA | Q6: IN ATTESA DI NORMALIZZAZIONE | S6: NON SCADUTA | T6: SOTTO CREDITO | U6: NON NORMALIZZABILE | V6: IN ATTESA DI NORMALIZZAZIONE
A7: ENRICA ANGELUCCI | B7: 02/11/2025 | C7: ATTIVAZIONE SIM MNP - MASSMARKET | D7: 8939108640012793084 | E7: 3382561536 | F7: NO | G7: 45993 | H7: 46003 | N7: SCADUTA | O7: SCADUTA | Q7: NON NORMALIZZABILE | S7: GESTIONE NON ATTIVA | T7: MNP OUT | U7: MNP OUT | V7: NON NORMALIZZABILE
A8: FEDERICA LACARBONARA | B8: 03/11/2025 | C8: ATTIVAZIONE SIM MNP - MASSMARKET | D8: 8939108640012792656 | E8: 3294266939 | F8: NO | G8: 45994 | H8: 46004 | N8: SCADUTA | O8: SCADUTA | Q8: MNP OUT | T8: NON NORMALIZZABILE | V8: MNP OUT
A9: ANDREA VERGALITO | B9: 03/11/2025 | C9: ATTIVAZIONE SIM MNP - MASSMARKET | D9: 8939108640011143612 | E9: 3428333912 | F9: SI | G9: 45994 | H9: 46004 | N9: SCADUTA | O9: SCADUTA
A10: ENRICA ANGELUCCI | B10: 03/11/2025 | C10: ATTIVAZIONE SIM MNP - CONVERGENZA FISSO - MOBILE | D10: 8939108650003652108 | E10: 3490859404 | F10: NO | G10: 45994 | H10: 46004 | N10: SCADUTA | O10: SCADUTA
A11: ANDREA VERGALITO | B11: 08/11/2025 | C11: ATTIVAZIONE SIM MNP - MASSMARKET | D11: 8939108640012792870 | E11: 3467556719 | F11: SI | G11: 45999 | H11: 46009 | N11: SCADUTA | O11: SCADUTA
A12: FEDERICA LACARBONARA | B12: 08/11/2025 | C12: ATTIVAZIONE SIM MNP - MASSMARKET | D12: 8939108640011144990 | E12: 3791959562 | F12: NO | G12: 45999 | H12: 46009 | N12: SCADUTA | O12: SCADUTA
A13: FEDERICA LACARBONARA | B13: 08/11/2025 | C13: SIM SCONTATA - ATTIVAZIONE SIM MNP - CONV. FISSO - MOBILE | D13: 8939108640012793092 | E13: 3713400403 | F13: SI | G13: 45999 | H13: 46009 | N13: SCADUTA | O13: SCADUTA
A14: ENRICA ANGELUCCI | B14: 09/11/2025 | C14: ATTIVAZIONE SIM MNP - MASSMARKET | D14: 8939108640012795261 | E14: 3400532574 | F14: SI | G14: 46000 | H14: 46010 | N14: SCADUTA | O14: SCADUTA
A15: ANDREA VERGALITO | B15: 10/11/2025 | C15: ATTIVAZIONE SIM MNP - MASSMARKET | D15: 8939108640012795287 | E15: 3890213440 | F15: NO | G15: 46001 | H15: 46011 | N15: SCADUTA | O15: SCADUTA
A16: ANDREA VERGALITO | B16: 10/11/2025 | C16: ATTIVAZIONE SIM MNP - CONVERGENZA FISSO - MOBILE | D16: 8939108640011144040 | E16: 3515539921 | F16: SI | G16: 46001 | H16: 46011 | N16: SCADUTA | O16: SCADUTA
A17: ENRICA ANGELUCCI | B17: 13/11/2025 | C17: ATTIVAZIONE SIM MNP - MASSMARKET | D17: 8939108660014740149 | E17: 3383621757 | F17: NO | G17: 46004 | H17: 46014 | N17: SCADUTA | O17: SCADUTA
A18: ANDREA VERGALITO | B18: 13/11/2025 | C18: ATTIVAZIONE SIM MNP - CONVERGENZA FISSO - MOBILE | D18: 8939108660014739349 | E18: 3469467111 | F18: NO | G18: 46004 | H18: 46014 | N18: SCADUTA | O18: SCADUTA
A19: ENRICA ANGELUCCI | B19: 14/11/2025 | C19: ATTIVAZIONE SIM MNP - CONVERGENZA FISSO - MOBILE | D19: 8939108660014739323 | E19: 3489174140 | F19: NO | G19: 46005 | H19: 46015 | N19: SCADUTA | O19: SCADUTA
A20: ENRICA ANGELUCCI | B20: 15/11/2025 | C20: ATTIVAZIONE SIM MNP - MASSMARKET | D20: 8939108660014739406 | E20: 3387471880 | F20: SI | G20: 46006 | H20: 46016 | N20: SCADUTA | O20: SCADUTA
... A44: ANDREA VERGALITO | B44: 30/11/2025 | C44: ATTIVAZIONE SIM MNP - CONVERGENZA FISSO - MOBILE | D44: 8939108660014739752 | E44: 3458955561 | F44: NO | G44: 46006 | H44: 46027 | N44: SCADUTA | O44: SCADUTA

Sheet FAMILY Megalò
A1: CHIETI SCALO | B1: Column2 | C1: NEGOZIO DI RIFERIMENTO | D1: Column4 | E1: Column5 | F1: SELEZIONARE ESITO DAL MENÙ A TENDINA E | G1: Column7 | H1: Column8 | I1: Column9 | J1: Column10 | K1: Column11 | L1: Column12 | M1: Column13 | N1: Column14 | O1: Column15 | P1: Column16 | Q1: Column17
F2: AGGIUNGERE UN COMMENTO
A3: OPERATORE | B3: DATA | C3: TITOLO | D3: SIM | E3: TELEFONO | F3: DATA DI SCADENZA | G3: ESITO | H3: ESITO BO | I3: NOTE BO | J3: ESITO SUITE
A4: ALESSANDRA PROPERZIO | B4: 01/11/2025 | C4: ATTIVAZIONE CONVERGENZA FISSO - MOBILE | D4: 8939108640012762287 | E4: 3276143324 | F4: 45992 | G4: INSERITA IN FAMIGLIA | J4: OK | K4: SCADUTA | L4: SCADUTA | M4: NON SCADUTA | O4: TIPOLOGIA | Q4: INSERITA IN FAMIGLIA
A5: ALESSANDRA PROPERZIO | B5: 01/11/2025 | C5: ATTIVAZIONE CONVERGENZA FISSO - MOBILE | D5: 8939108630011277718 | E5: 3476840957 | F5: 45992 | G5: INSERITA IN FAMIGLIA | J5: OK | K5: SCADUTA | L5: ATTIVITÀ SCADUTA | M5: INSERITA IN FAMIGLIA | O5: SCADUTA | Q5: IN ATTESA DI NORMALIZZAZIONE
A6: ALESSANDRA PROPERZIO | B6: 03/11/2025 | C6: ATTIVAZIONE CONVERGENZA FISSO - MOBILE | D6: 8939108640015181642 | E6: 3408699180 | F6: 45994 | G6: INSERITA IN FAMIGLIA | J6: OK | K6: SCADUTA | M6: IN ATTESA DI NORMALIZZAZIONE | O6: NON SCADUTA | Q6: NON NORMALIZZABILE
A7: STEFANO COLANTONIO | B7: 03/11/2025 | C7: ATTIVAZIONE CONVERGENZA FISSO - MOBILE | D7: 8939108640012761271 | E7: 3515651593 | F7: 45994 | G7: INSERITA IN FAMIGLIA | J7: OK | K7: SCADUTA | M7: NON NORMALIZZABILE | Q7: MNP OUT
A8: EMILIANO MARSILI | B8: 05/11/2025 | C8: ATTIVAZIONE CONVERGENZA FISSO - MOBILE | D8: 8939108640012762394 | E8: 3497510962 | F8: 45996 | G8: INSERITA IN FAMIGLIA | J8: OK | K8: SCADUTA | M8: MNP OUT
A9: EMILIANO MARSILI | B9: 05/11/2025 | C9: ATTIVAZIONE CONVERGENZA FISSO - MOBILE | D9: 8939108640015181741 | E9: 3925147277 | F9: 45996 | G9: INSERITA IN FAMIGLIA | J9: OK | K9: SCADUTA
A10: EMILIANO MARSILI | B10: 05/11/2025 | C10: ATTIVAZIONE CONVERGENZA FISSO - MOBILE | D10: 8939108640015181626 | E10: 3925147277 | F10: 45996 | G10: INSERITA IN FAMIGLIA | J10: OK | K10: SCADUTA
A11: EMILIANO MARSILI | B11: 06/11/2025 | C11: ATTIVAZIONE CONVERGENZA FISSO - MOBILE | D11: 8939108640015181949 | E11: 3420303782 | F11: 46007 | G11: IN ATTESA DI NORMALIZZAZIONE | K11: SCADUTA
A12: EMILIANO MARSILI | B12: 07/11/2025 | C12: ATTIVAZIONE CONVERGENZA FISSO - MOBILE | D12: 8939108640015181972 | E12: 3339323992 | F12: 45998 | G12: INSERITA IN FAMIGLIA | J12: OK | K12: SCADUTA
A13: STEFANO COLANTONIO | B13: 10/11/2025 | C13: ATTIVAZIONE CONVERGENZA FISSO - MOBILE | D13: 8939108640015181329 | E13: 3450475906 | F13: 46011 | G13: IN ATTESA DI NORMALIZZAZIONE | K13: SCADUTA
A14: STEFANO COLANTONIO | B14: 13/11/2025 | C14: ATTIVAZIONE CONVERGENZA FISSO - MOBILE | D14: 8939108640012760620 | E14: 3282757034 | F14: 46004 | G14: INSERITA IN FAMIGLIA | J14: OK | K14: SCADUTA
A15: EMILIANO MARSILI | B15: 14/11/2025 | C15: ATTIVAZIONE CONVERGENZA FISSO - MOBILE | D15: 8939108640015181733 | E15: 3928477531 | F15: 46005 | G15: INSERITA IN FAMIGLIA | J15: OK | K15: SCADUTA
A16: EMILIANO MARSILI | B16: 14/11/2025 | C16: ATTIVAZIONE CONVERGENZA FISSO - MOBILE | D16: 8939108660014936424 | E16: 3277560823 | F16: 46005 | G16: INSERITA IN FAMIGLIA | J16: OK | K16: SCADUTA
A17: EMILIANO MARSILI | B17: 16/11/2025 | C17: ATTIVAZIONE CONVERGENZA FISSO - MOBILE | D17: 8939108660014936523 | E17: 3488430246 | F17: 46006 | G17: INSERITA IN FAMIGLIA | J17: OK | K17: SCADUTA
A18: EMILIANO MARSILI | B18: 18/11/2025 | C18: ATTIVAZIONE CONVERGENZA FISSO - MOBILE | D18: 8939108660014936705 | E18: 3459264297 | F18: 46006 | G18: INSERITA IN FAMIGLIA | J18: OK | K18: SCADUTA
A19: EMILIANO MARSILI | B19: 19/11/2025 | C19: ATTIVAZIONE CONVERGENZA FISSO - MOBILE | D19: 8939108660014936879 | E19: 3517697298 | F19: 46006 | G19: INSERITA IN FAMIGLIA | J19: OK | K19: SCADUTA
A20: EMILIANO MARSILI | B20: 20/11/2025 | C20: ATTIVAZIONE CONVERGENZA FISSO - MOBILE | D20: 8939108660014936952 | E20: 3896362845 | F20: 46011 | G20: IN ATTESA DI NORMALIZZAZIONE | K20: SCADUTA
A21: STEFANO COLANTONIO | B21: 28/11/2025 | C21: ATTIVAZIONE CONVERGENZA FISSO - MOBILE | D21: 8939108660014936846 | E21: 3208113132 | F21: 46006 | G21: INSERITA IN FAMIGLIA | J21: OK | K21: SCADUTA
A22: STEFANO COLANTONIO | B22: 29/11/2025 | C22: ATTIVAZIONE CONVERGENZA FISSO - MOBILE | D22: 8939108660014937067 | E22: 3283444228 | F22: 46006 | G22: INSERITA IN FAMIGLIA | J22: OK | K22: SCADUTA
A23: ALESSANDRA PROPERZIO | B23: 30/11/2025 | C23: ATTIVAZIONE CONVERGENZA FISSO - MOBILE | D23: 8939108660014937372 | E23: 3467675632 | F23: 46011 | G23: IN ATTESA DI NORMALIZZAZIONE | K23: SCADUTA

Sheet MNP Megalò
A1: CHIETI SCALO | B1: Column2 | C1: NEGOZIO DI RIFERIMENTO | D1: Column4 | E1: Column5 | F1: Column6 | G1: Column7 | H1: SELEZIONARE ESITO DAL MENÙ A TENDINA E | I1: Column9 | J1: Column10 | K1: Column11 | L1: Column12 | M1: Column13 | N1: Column14 | O1: Column15 | P1: Column16 | Q1: Column17 | R1: Column18 | S1: Column19 | T1: Column20 | U1: Column21 | V1: Column22 | W1: Column23
H2: AGGIUNGERE UN COMMENTO
A3: OPERATORE | B3: DATA | C3: TITOLO | D3: SIM | E3: TELEFONO | F3: VIRTUALE | G3: DATA DI SCADENZA MNP | H3: DATA DI SCADENZA T+1 | I3: ESITO MNP | J3: ESITO RINNOVO T+1 | K3: ESITO BO | L3: NOTE BO | M3: ESITO SUITE
A4: ALESSANDRA PROPERZIO | B4: 01/11/2025 | C4: ATTIVAZIONE SIM MNP - MASSMARKET | D4: 8939108640012761313 | E4: 3427590588 | F4: NO | G4: 45992 | H4: 46002 | I4: MNP EFFETTUATA | J4: RINNOVO EFFETTUATO | M4: OK | N4: SCADUTA | O4: SCADUTA | P4: SCADUTA | Q4: NON SCADUTA | R4: GESTIONE NON ATTIVA | S4: TIPOLOGIA | T4: NON SCADUTA T1 | U4: MNP EFFETTUATA | V4: ESITO BO
A5: ALESSANDRA PROPERZIO | B5: 01/11/2025 | C5: ATTIVAZIONE SIM MNP - MASSMARKET | D5: 8939108630011365539 | E5: 3802669061 | F5: NO | G5: 45992 | H5: 46002 | I5: MNP EFFETTUATA | J5: RINNOVO EFFETTUATO | M5: OK | N5: SCADUTA | O5: SCADUTA | P5: ATTIVITÀ SCADUTA | Q5: MNP EFFETTUATA | S5: SCADUTA | T5: RINNOVO EFFETTUATO | U5: IN ATTESA DI NORMALIZZAZIONE | V5: OK
A6: ALESSANDRA PROPERZIO | B6: 01/11/2025 | C6: ATTIVAZIONE SIM MNP - MASSMARKET | D6: 8939108630011277668 | E6: 3495511036 | F6: NO | G6: 45992 | H6: 46002 | I6: MNP EFFETTUATA | J6: RINNOVO EFFETTUATO | M6: OK | N6: SCADUTA | O6: SCADUTA | P6: GESTIONE NON ATTIVA | Q6: IN ATTESA DI NORMALIZZAZIONE | S6: NON SCADUTA | T6: SOTTO CREDITO | U6: NON NORMALIZZABILE | V6: IN ATTESA DI NORMALIZZAZIONE
A7: ALESSANDRA PROPERZIO | B7: 01/11/2025 | C7: ATTIVAZIONE SIM MNP - CONVERGENZA FISSO - MOBILE | D7: 8939108640012762287 | E7: 3276143324 | F7: SI | G7: 45992 | H7: 46002 | I7: MNP EFFETTUATA | J7: RINNOVO EFFETTUATO | M7: OK | N7: SCADUTA | O7: SCADUTA | Q7: NON NORMALIZZABILE | S7: GESTIONE NON ATTIVA | T7: MNP OUT | U7: MNP OUT | V7: NON NORMALIZZABILE
A8: ALESSANDRA PROPERZIO | B8: 01/11/2025 | C8: ATTIVAZIONE SIM MNP - CONVERGENZA FISSO - MOBILE | D8: 8939108630011277718 | E8: 3476840957 | F8: NO | G8: 45992 | H8: 46002 | I8: MNP EFFETTUATA | J8: RINNOVO EFFETTUATO | M8: OK | N8: SCADUTA | O8: SCADUTA | Q8: MNP OUT | T8: NON NORMALIZZABILE | V8: MNP OUT
A9: STEFANO COLANTONIO | B9: 03/11/2025 | C9: ATTIVAZIONE SIM MNP - MASSMARKET | D9: 8939108640015181659 | E9: 3408255922 | F9: NO | G9: 45994 | H9: 46004 | I9: MNP EFFETTUATA | J9: RINNOVO EFFETTUATO | M9: OK | N9: SCADUTA | O9: SCADUTA
A10: ALESSANDRA PROPERZIO | B10: 03/11/2025 | C10: ATTIVAZIONE SIM MNP - CONVERGENZA FISSO - MOBILE | D10: 8939108640015181642 | E10: 3408699180 | F10: NO | G10: 45994 | H10: 46004 | I10: MNP EFFETTUATA | J10: RINNOVO EFFETTUATO | M10: OK | N10: SCADUTA | O10: SCADUTA
A11: STEFANO COLANTONIO | B11: 03/11/2025 | C11: ATTIVAZIONE SIM MNP - CONVERGENZA FISSO - MOBILE | D11: 8939108640012761271 | E11: 3515651593 | F11: NO | G11: 45994 | H11: 46004 | I11: MNP EFFETTUATA | J11: RINNOVO EFFETTUATO | M11: OK | N11: SCADUTA | O11: SCADUTA
A12: STEFANO COLANTONIO | B12: 04/11/2025 | C12: ATTIVAZIONE SIM MNP - MASSMARKET | D12: 8939108640012761198 | E12: 3890287294 | F12: NO | G12: 45995 | H12: 46005 | I12: MNP EFFETTUATA | J12: RINNOVO EFFETTUATO | M12: OK | N12: SCADUTA | O12: SCADUTA
A13: EMILIANO MARSILI | B13: 05/11/2025 | C13: SIM SCONTATA - ATTIVAZIONE SIM MNP - CONV. FISSO - MOBILE | D13: 8939108640015181550 | E13: 3894541833 | F13: NO | G13: 45996 | H13: 46006 | I13: MNP EFFETTUATA | J13: RINNOVO EFFETTUATO | M13: OK | N13: SCADUTA | O13: SCADUTA
A14: EMILIANO MARSILI | B14: 05/11/2025 | C14: ATTIVAZIONE SIM MNP - CONVERGENZA FISSO - MOBILE | D14: 8939108640012762394 | E14: 3497510962 | F14: NO | G14: 45996 | H14: 46006 | I14: MNP EFFETTUATA | J14: RINNOVO EFFETTUATO | M14: OK | N14: SCADUTA | O14: SCADUTA
A15: EMILIANO MARSILI | B15: 05/11/2025 | C15: ATTIVAZIONE SIM MNP - CONVERGENZA FISSO - MOBILE | D15: 8939108640015181741 | E15: 3925147277 | F15: SI | G15: 45996 | H15: 46006 | I15: MNP EFFETTUATA | J15: RINNOVO EFFETTUATO | M15: OK | N15: SCADUTA | O15: SCADUTA
A16: EMILIANO MARSILI | B16: 05/11/2025 | C16: ATTIVAZIONE SIM MNP - CONVERGENZA FISSO - MOBILE | D16: 8939108640015181626 | E16: 3925147277 | F16: SI | G16: 45996 | H16: 46006 | I16: MNP EFFETTUATA | J16: RINNOVO EFFETTUATO | M16: OK | N16: SCADUTA | O16: SCADUTA
A17: EMILIANO MARSILI | B17: 06/11/2025 | C17: ATTIVAZIONE SIM MNP - CONVERGENZA FISSO - MOBILE | D17: 8939108640015181949 | E17: 3420303782 | F17: NO | G17: 45997 | H17: 46007 | I17: MNP EFFETTUATA | J17: RINNOVO EFFETTUATO | M17: OK | N17: SCADUTA | O17: SCADUTA
A18: EMILIANO MARSILI | B18: 07/11/2025 | C18: ATTIVAZIONE SIM MNP - CONVERGENZA FISSO - MOBILE | D18: 8939108640015181972 | E18: 3339323992 | F18: NO | G18: 45998 | H18: 46008 | I18: MNP EFFETTUATA | J18: RINNOVO EFFETTUATO | M18: OK | N18: SCADUTA | O18: SCADUTA
A19: ALESSANDRA PROPERZIO | B19: 09/11/2025 | C19: ATTIVAZIONE SIM MNP - MASSMARKET | D19: 8939108640015181568 | E19: 336664045 | F19: NO | G19: 46000 | H19: 46010 | I19: MNP EFFETTUATA | N19: SCADUTA | O19: SCADUTA
A20: STEFANO COLANTONIO | B20: 12/11/2025 | C20: ATTIVAZIONE SIM MNP - MASSMARKET | D20: 8939108630011277700 | E20: 3388101397 | F20: NO | G20: 46003 | H20: 46013 | I20: MNP EFFETTUATA | N20: SCADUTA | O20: SCADUTA
A21: STEFANO COLANTONIO | B21: 13/11/2025 | C21: ATTIVAZIONE SIM MNP - CONVERGENZA FISSO - MOBILE | D21: 8939108640012760620 | E21: 3282757034 | F21: SI | G21: 46004 | H21: 46014 | I21: MNP EFFETTUATA | N21: SCADUTA | O21: SCADUTA
A22: EMILIANO MARSILI | B22: 14/11/2025 | C22: ATTIVAZIONE SIM MNP - CONVERGENZA FISSO - MOBILE | D22: 8939108640015181733 | E22: 3928477531 | F22: NO | G22: 46005 | H22: 46015 | I22: MNP EFFETTUATA | N22: SCADUTA | O22: SCADUTA
A23: EMILIANO MARSILI | B23: 14/11/2025 | C23: ATTIVAZIONE SIM MNP - CONVERGENZA FISSO - MOBILE | D23: 8939108660014936424 | E23: 3277560823 | F23: NO | G23: 46005 | H23: 46015 | I23: MNP EFFETTUATA | N23: SCADUTA | O23: SCADUTA
A24: EMILIANO MARSILI | B24: 16/11/2025 | C24: ATTIVAZIONE SIM MNP - MASSMARKET | D24: 8939108660014936515 | E24: 3318662172 | F24: NO | G24: 46006 | H24: 46017 | I24: MNP EFFETTUATA | N24: SCADUTA | O24: SCADUTA
A25: STEFANO COLANTONIO | B25: 16/11/2025 | C25: SIM SCONTATA - ATTIVAZIONE SIM MNP - CONV. FISSO - MOBILE | D25: 8939108660014937307 | E25: 3511838840 | F25: NO | G25: 46006 | H25: 46017 | I25: MNP EFFETTUATA | N25: SCADUTA | O25: SCADUTA
A26: STEFANO COLANTONIO | B26: 18/11/2025 | C26: ATTIVAZIONE SIM MNP - MASSMARKET | D26: 8939108660014937356 | E26: 3891148508 | F26: NO | G26: 46006 | H26: 46019 | I26: MNP EFFETTUATA | N26: SCADUTA | O26: SCADUTA
A27: EMILIANO MARSILI | B27: 18/11/2025 | C27: ATTIVAZIONE SIM MNP - MASSMARKET | D27: 8939108660014936929 | E27: 3293250602 | F27: NO | G27: 46006 | H27: 46019 | I27: MNP EFFETTUATA | N27: SCADUTA | O27: SCADUTA
A28: EMILIANO MARSILI | B28: 18/11/2025 | C28: ATTIVAZIONE SIM MNP - ETNICO | D28: 8939108660014937117 | E28: 3512627861 | F28: NO | G28: 46006 | H28: 46019 | I28: MNP EFFETTUATA | N28: SCADUTA | O28: SCADUTA
A29: EMILIANO MARSILI | B29: 19/11/2025 | C29: ATTIVAZIONE SIM MNP - MASSMARKET | D29: 8939108660014936895 | E29: 3274803205 | F29: NO | G29: 46006 | H29: 46020 | I29: MNP EFFETTUATA | J29: RINNOVO EFFETTUATO | M29: OK | N29: SCADUTA | O29: SCADUTA
A30: EMILIANO MARSILI | B30: 19/11/2025 | C30: ATTIVAZIONE SIM MNP - CONVERGENZA FISSO - MOBILE | D30: 8939108660014936879 | E30: 3517697298 | F30: NO | G30: 46006 | H30: 46020 | I30: MNP EFFETTUATA | J30: RINNOVO EFFETTUATO | M30: OK | N30: SCADUTA | O30: SCADUTA
A31: EMILIANO MARSILI | B31: 20/11/2025 | C31: ATTIVAZIONE SIM MNP - CONVERGENZA FISSO - MOBILE | D31: 8939108660014936952 | E31: 3896362845 | F31: NO | G31: 46006 | H31: 46021 | I31: MNP EFFETTUATA | J31: RINNOVO EFFETTUATO | M31: OK | N31: SCADUTA | O31: SCADUTA
A32: EMILIANO MARSILI | B32: 21/11/2025 | C32: SIM SCONTATA - ATTIVAZIONE SIM MNP - CONV. FISSO - MOBILE | D32: 8939108660014936945 | E32: 3297711428 | F32: NO | G32: 46006 | H32: 46022 | I32: MNP EFFETTUATA | J32: RINNOVO EFFETTUATO | M32: OK | N32: SCADUTA | O32: SCADUTA
A33: STEFANO COLANTONIO | B33: 22/11/2025 | C33: SIM SCONTATA - ATTIVAZIONE SIM MNP - CONV. FISSO - MOBILE | D33: 8939108660014936762 | E33: 3478508845 | F33: NO | G33: 46006 | H33: 46023 | I33: MNP EFFETTUATA | J33: RINNOVO EFFETTUATO | M33: OK | N33: SCADUTA | O33: SCADUTA
A34: ALESSANDRA PROPERZIO | B34: 23/11/2025 | C34: ATTIVAZIONE SIM MNP - MASSMARKET | D34: 8939108660014936820 | E34: 3663923574 | F34: NO | G34: 46006 | H34: 46024 | I34: MNP EFFETTUATA | J34: RINNOVO EFFETTUATO | M34: OK | N34: SCADUTA | O34: NON SCADUTA T1
A35: ALESSANDRA PROPERZIO | B35: 24/11/2025 | C35: ATTIVAZIONE SIM MNP - MASSMARKET | D35: 8939108660014936481 | E35: 3201991104 | F35: NO | G35: 46006 | H35: 46025 | I35: MNP EFFETTUATA | J35: RINNOVO EFFETTUATO | M35: OK | N35: SCADUTA | O35: NON SCADUTA T1
A36: EMILIANO MARSILI | B36: 24/11/2025 | C36: SIM SCONTATA - ATTIVAZIONE SIM MNP - CONV. FISSO - MOBILE | D36: 8939108660014936937 | E36: 3295670682 | F36: NO | G36: 46011 | H36: 46025 | I36: IN ATTESA DI NORMALIZZAZIONE | J36: SOTTO CREDITO | N36: SCADUTA | O36: NON SCADUTA T1
A37: STEFANO COLANTONIO | B37: 25/11/2025 | C37: ATTIVAZIONE SIM MNP - MASSMARKET | D37: 8939108660014936663 | E37: 3927810389 | F37: NO | G37: 46006 | H37: 46026 | I37: MNP EFFETTUATA | J37: RINNOVO EFFETTUATO | M37: OK | N37: SCADUTA | O37: NON SCADUTA T1
A38: ALESSANDRA PROPERZIO | B38: 25/11/2025 | C38: SIM SCONTATA - ATTIVAZIONE SIM MNP - CONV. FISSO - MOBILE | D38: 8939108660014936630 | E38: 3520454789 | F38: SI | G38: 46006 | H38: 46026 | I38: MNP EFFETTUATA | J38: RINNOVO EFFETTUATO | M38: OK | N38: SCADUTA | O38: NON SCADUTA T1
A39: STEFANO COLANTONIO | B39: 26/11/2025 | C39: ATTIVAZIONE SIM MNP - MASSMARKET | D39: 8939108660014937042 | E39: 33117707754 | F39: NO | G39: 46006 | H39: 46027 | I39: MNP EFFETTUATA | J39: RINNOVO EFFETTUATO | M39: OK | N39: SCADUTA | O39: NON SCADUTA T1
A40: EMILIANO MARSILI | B40: 27/11/2025 | C40: ATTIVAZIONE SIM MNP - MASSMARKET | D40: 8939108660014937091 | E40: 3337828304 | F40: NO | G40: 46006 | H40: 46027 | I40: MNP EFFETTUATA | J40: SOTTO CREDITO | N40: SCADUTA | O40: NON SCADUTA T1
...

Sheet FAMILY CSA
A1: SANTANGELO | B1: Column2 | C1: NEGOZIO DI RIFERIMENTO | D1: Column4 | E1: Column5 | F1: SELEZIONARE ESITO DAL MENÙ A TENDINA E | G1: Column7 | H1: Column8 | I1: Column9 | J1: Column10 | K1: Column11 | L1: Column12 | M1: Column13 | N1: Column14 | O1: Column15 | P1: Column16 | Q1: Column17
F2: AGGIUNGERE UN COMMENTO
A3: OPERATORE | B3: DATA | C3: TITOLO | D3: SIM | E3: TELEFONO | F3: DATA DI SCADENZA | G3: ESITO | H3: ESITO BO | I3: NOTE BO | J3: ESITO SUITE
A4: KATIUSKA GEMMA DI GIOVANNI | B4: 03/11/2025 | C4: ATTIVAZIONE CONVERGENZA FISSO - MOBILE | D4: 8939108640011148975 | E4: 3388332728 | F4: 45994 | G4: INSERITA IN FAMIGLIA | J4: OK | K4: SCADUTA | L4: SCADUTA | M4: NON SCADUTA | O4: TIPOLOGIA | Q4: INSERITA IN FAMIGLIA
A5: KATIUSKA GEMMA DI GIOVANNI | B5: 05/11/2025 | C5: ATTIVAZIONE CONVERGENZA FISSO - MOBILE | D5: 8939108640011149460 | E5: 3475539071 | F5: 45996 | G5: INSERITA IN FAMIGLIA | J5: OK | K5: SCADUTA | L5: ATTIVITÀ SCADUTA | M5: INSERITA IN FAMIGLIA | O5: SCADUTA | Q5: IN ATTESA DI NORMALIZZAZIONE
A6: KATIUSKA GEMMA DI GIOVANNI | B6: 05/11/2025 | C6: ATTIVAZIONE CONVERGENZA FISSO - MOBILE | D6: 8939108640011148751 | E6: 3499506877 | F6: 45996 | G6: INSERITA IN FAMIGLIA | J6: OK | K6: SCADUTA | M6: IN ATTESA DI NORMALIZZAZIONE | O6: NON SCADUTA | Q6: NON NORMALIZZABILE
A7: KATIUSKA GEMMA DI GIOVANNI | B7: 08/11/2025 | C7: ATTIVAZIONE CONVERGENZA FISSO - MOBILE | D7: 8939108640011148728 | E7: 3450205656 | F7: 45999 | G7: INSERITA IN FAMIGLIA | J7: OK | K7: SCADUTA | M7: NON NORMALIZZABILE | Q7: MNP OUT
A8: ANTONIO SACCO | B8: 09/11/2025 | C8: ATTIVAZIONE CONVERGENZA FISSO - MOBILE | D8: 8939108640011149403 | E8: 3356585530 | F8: 46000 | G8: INSERITA IN FAMIGLIA | J8: OK | K8: SCADUTA | M8: MNP OUT
A9: ANTONIO SACCO | B9: 09/11/2025 | C9: ATTIVAZIONE CONVERGENZA FISSO - MOBILE | D9: 8939108640011149718 | E9: 3499835631 | F9: 46000 | G9: INSERITA IN FAMIGLIA | J9: OK | K9: SCADUTA
A10: ANTONIO SACCO | B10: 09/11/2025 | C10: ATTIVAZIONE CONVERGENZA FISSO - MOBILE | D10: 8939108640012796954 | E10: 3341267722 | F10: 46000 | G10: INSERITA IN FAMIGLIA | J10: OK | K10: SCADUTA
A11: ANTONIO SACCO | B11: 09/11/2025 | C11: ATTIVAZIONE CONVERGENZA FISSO - MOBILE | D11: 8939108640012796707 | E11: 3801974997 | F11: 46000 | G11: NON NORMALIZZABILE | J11: DA ELIMINARE | K11: SCADUTA
A12: ANTONIO SACCO | B12: 09/11/2025 | C12: ATTIVAZIONE CONVERGENZA FISSO - MOBILE | D12: 8939108640012797028 | E12: 3314423145 | F12: 46000 | G12: INSERITA IN FAMIGLIA | J12: OK | K12: SCADUTA
A13: ANTONIO SACCO | B13: 09/11/2025 | C13: ATTIVAZIONE CONVERGENZA FISSO - MOBILE | D13: 8939108640011149064 | E13: 3801974997 | F13: 46000 | G13: MNP OUT | J13: DA ELIMINARE | K13: SCADUTA
A14: ANTONIO SACCO | B14: 10/11/2025 | C14: ATTIVAZIONE CONVERGENZA FISSO - MOBILE | D14: 8939108640011149296 | E14: 3516230326 | F14: 46001 | G14: INSERITA IN FAMIGLIA | J14: OK | K14: SCADUTA
A15: ANTONIO SACCO | B15: 10/11/2025 | C15: ATTIVAZIONE CONVERGENZA FISSO - MOBILE | D15: 8939108640011149247 | E15: 3351333190 | F15: 46001 | G15: INSERITA IN FAMIGLIA | J15: OK | K15: SCADUTA
A16: YUDITH HERNANDEZ GARCIA | B16: 12/11/2025 | C16: ATTIVAZIONE CONVERGENZA FISSO - MOBILE | D16: 8939108640011148850 | E16: 3318023757 | F16: 46003 | G16: INSERITA IN FAMIGLIA | J16: OK | K16: SCADUTA
A17: ANTONIO SACCO | B17: 13/11/2025 | C17: ATTIVAZIONE CONVERGENZA FISSO - MOBILE | D17: 8939108640011149759 | E17: 3473641890 | F17: 46004 | G17: INSERITA IN FAMIGLIA | J17: OK | K17: SCADUTA
A18: ANTONIO SACCO | B18: 13/11/2025 | C18: ATTIVAZIONE CONVERGENZA FISSO - MOBILE | D18: 8939108640012796731 | E18: 3489507337 | F18: 46004 | G18: INSERITA IN FAMIGLIA | J18: OK | K18: SCADUTA
A19: YUDITH HERNANDEZ GARCIA | B19: 16/11/2025 | C19: ATTIVAZIONE CONVERGENZA FISSO - MOBILE | D19: 8939108640012796301 | E19: 3891773471 | F19: 46006 | G19: INSERITA IN FAMIGLIA | J19: OK | K19: SCADUTA
A20: YUDITH HERNANDEZ GARCIA | B20: 17/11/2025 | C20: ATTIVAZIONE CONVERGENZA FISSO - MOBILE | D20: 8939108660014738440 | E20: 3331095959 | F20: 46006 | G20: INSERITA IN FAMIGLIA | J20: OK | K20: SCADUTA
... A30: YUDITH HERNANDEZ GARCIA | B30: 30/11/2025 | C30: ATTIVAZIONE CONVERGENZA FISSO - MOBILE | D30: 8939108660014738341 | E30: 3279486803 | F30: 46006 | G30: INSERITA IN FAMIGLIA | J30: OK | K30: SCADUTA

Sheet MNP CSA
A1: SANTANGELO | B1: Column2 | C1: NEGOZIO DI RIFERIMENTO | D1: Column4 | E1: Column5 | F1: Column6 | G1: Column7 | H1: SELEZIONARE ESITO DAL MENÙ A TENDINA E | I1: Column9 | J1: Column10 | K1: Column11 | L1: Column12 | M1: Column13 | N1: Column14 | O1: Column15 | P1: Column16 | Q1: Column17 | R1: Column18 | S1: Column19 | T1: Column20 | U1: Column21 | V1: Column22 | W1: Column23
H2: AGGIUNGERE UN COMMENTO
A3: OPERATORE | B3: DATA | C3: TITOLO | D3: SIM | E3: TELEFONO | F3: VIRTUALE | G3: DATA DI SCADENZA MNP | H3: DATA DI SCADENZA T+1 | I3: ESITO MNP | J3: ESITO RINNOVO T+1 | K3: ESITO BO | L3: NOTE BO | M3: ESITO SUITE
A4: MARIKA OTTAVIANO | B4: 01/11/2025 | C4: ATTIVAZIONE SIM MNP - MASSMARKET | D4: 8939108640011149544 | E4: 3914256630 | F4: NO | G4: 45992 | H4: 46002 | I4: MNP EFFETTUATA | K4: OK | M4: OK | N4: SCADUTA | O4: SCADUTA | P4: SCADUTA | Q4: NON SCADUTA | R4: GESTIONE NON ATTIVA | S4: TIPOLOGIA | T4: NON SCADUTA T1 | U4: MNP EFFETTUATA | V4: ESITO BO
A5: YUDITH HERNANDEZ GARCIA | B5: 01/11/2025 | C5: ATTIVAZIONE SIM MNP - MASSMARKET | D5: 8939108640011150096 | E5: 3805813875 | F5: SI | G5: 45992 | H5: 46002 | I5: MNP EFFETTUATA | K5: OK | M5: OK | N5: SCADUTA | O5: SCADUTA | P5: ATTIVITÀ SCADUTA | Q5: MNP EFFETTUATA | S5: SCADUTA | T5: RINNOVO EFFETTUATO | U5: IN ATTESA DI NORMALIZZAZIONE | V5: OK
A6: MARIKA OTTAVIANO | B6: 01/11/2025 | C6: ATTIVAZIONE SIM MNP - MASSMARKET | D6: 8939108640011149171 | E6: 3917635351 | F6: NO | G6: 45992 | H6: 46002 | I6: MNP EFFETTUATA | K6: OK | M6: OK | N6: SCADUTA | O6: SCADUTA | P6: GESTIONE NON ATTIVA | Q6: IN ATTESA DI NORMALIZZAZIONE | S6: NON SCADUTA | T6: SOTTO CREDITO | U6: NON NORMALIZZABILE | V6: IN ATTESA DI NORMALIZZAZIONE
A7: KATIUSKA GEMMA DI GIOVANNI | B7: 02/11/2025 | C7: ATTIVAZIONE SIM MNP - MASSMARKET | D7: 8939108640012796210 | E7: 3406224545 | F7: SI | G7: 45993 | H7: 46003 | I7: MNP EFFETTUATA | K7: OK | M7: OK | N7: SCADUTA | O7: SCADUTA | Q7: NON NORMALIZZABILE | S7: GESTIONE NON ATTIVA | T7: MNP OUT | U7: MNP OUT | V7: NON NORMALIZZABILE
A8: ANTONIO SACCO | B8: 03/11/2025 | C8: ATTIVAZIONE SIM MNP - MASSMARKET | D8: 8939108640011149775 | E8: 3270115318 | F8: SI | G8: 45994 | H8: 46004 | I8: MNP EFFETTUATA | K8: OK | M8: OK | N8: SCADUTA | O8: SCADUTA | Q8: MNP OUT | T8: NON NORMALIZZABILE | V8: MNP OUT
A9: KATIUSKA GEMMA DI GIOVANNI | B9: 03/11/2025 | C9: SIM SCONTATA - ATTIVAZIONE SIM MNP - CONV. FISSO - MOBILE | D9: 8939108640011149148 | E9: 3287790217 | F9: NO | G9: 45994 | H9: 46004 | I9: NON NORMALIZZABILE | K9: NON NORMALIZZABILE | M9: DA ELIMINARE | N9: SCADUTA | O9: SCADUTA
A10: KATIUSKA GEMMA DI GIOVANNI | B10: 03/11/2025 | C10: SIM SCONTATA - ATTIVAZIONE SIM MNP - CONV. FISSO - MOBILE | D10: 8939108640012796145 | E10: 3924814817 | F10: NO | G10: 45994 | H10: 46004 | I10: MNP EFFETTUATA | K10: OK | M10: OK | N10: SCADUTA | O10: SCADUTA
A11: KATIUSKA GEMMA DI GIOVANNI | B11: 03/11/2025 | C11: ATTIVAZIONE SIM MNP - CONVERGENZA FISSO - MOBILE | D11: 8939108640011148975 | E11: 3388332728 | F11: NO | G11: 45994 | H11: 46004 | I11: MNP EFFETTUATA | K11: OK | M11: OK | N11: SCADUTA | O11: SCADUTA
A12: KATIUSKA GEMMA DI GIOVANNI | B12: 04/11/2025 | C12: SIM SCONTATA - ATTIVAZIONE SIM MNP - CONV. FISSO - MOBILE | D12: 8939108640012796137 | E12: 3288365715 | F12: NO | G12: 45995 | H12: 46005 | I12: MNP EFFETTUATA | K12: OK | M12: OK | N12: SCADUTA | O12: SCADUTA
A13: YUDITH HERNANDEZ GARCIA | B13: 05/11/2025 | C13: ATTIVAZIONE SIM MNP - MASSMARKET | D13: 8939108640012796871 | E13: 3208529009 | F13: SI | G13: 45996 | H13: 46006 | I13: MNP EFFETTUATA | K13: OK | M13: OK | N13: SCADUTA | O13: SCADUTA
A14: KATIUSKA GEMMA DI GIOVANNI | B14: 05/11/2025 | C14: ATTIVAZIONE SIM MNP - CONVERGENZA FISSO - MOBILE | D14: 8939108640011149460 | E14: 3475539071 | F14: SI | G14: 45996 | H14: 46006 | I14: MNP EFFETTUATA | K14: OK | M14: OK | N14: SCADUTA | O14: SCADUTA
A15: KATIUSKA GEMMA DI GIOVANNI | B15: 05/11/2025 | C15: ATTIVAZIONE SIM MNP - CONVERGENZA FISSO - MOBILE | D15: 8939108640011148751 | E15: 3499506877 | F15: NO | G15: 45996 | H15: 46006 | I15: MNP EFFETTUATA | K15: OK | M15: OK | N15: SCADUTA | O15: SCADUTA
A16: YUDITH HERNANDEZ GARCIA | B16: 06/11/2025 | C16: ATTIVAZIONE SIM MNP - MASSMARKET | D16: 8939108640011149700 | E16: 3289350101 | F16: NO | G16: 45997 | H16: 46007 | I16: MNP EFFETTUATA | K16: OK | M16: OK | N16: SCADUTA | O16: SCADUTA
A17: KATIUSKA GEMMA DI GIOVANNI | B17: 08/11/2025 | C17: ATTIVAZIONE SIM MNP - MASSMARKET | D17: 8939108640011149486 | E17: 3899250684 | F17: NO | G17: 45999 | H17: 46009 | I17: MNP EFFETTUATA | K17: OK | M17: OK | N17: SCADUTA | O17: SCADUTA
A18: YUDITH HERNANDEZ GARCIA | B18: 08/11/2025 | C18: ATTIVAZIONE SIM MNP - MASSMARKET | D18: 8939108640011148942 | E18: 3890258459 | F18: NO | G18: 45999 | H18: 46009 | I18: MNP EFFETTUATA | K18: OK | M18: OK | N18: SCADUTA | O18: SCADUTA
A19: ANTONIO SACCO | B19: 09/11/2025 | C19: ATTIVAZIONE SIM MNP - CONVERGENZA FISSO - MOBILE | D19: 8939108640011149403 | E19: 3356585530 | F19: NO | G19: 46000 | H19: 46010 | I19: MNP EFFETTUATA | K19: OK | M19: OK | N19: SCADUTA | O19: SCADUTA
A20: ANTONIO SACCO | B20: 09/11/2025 | C20: ATTIVAZIONE SIM MNP - CONVERGENZA FISSO - MOBILE | D20: 8939108640012796954 | E20: 3341267722 | F20: NO | G20: 46000 | H20: 46010 | I20: MNP EFFETTUATA | K20: OK | M20: OK | N20: SCADUTA | O20: SCADUTA
... A25: ANTONIO SACCO | B25: 10/11/2025 | C25: ATTIVAZIONE SIM MNP - CONVERGENZA FISSO - MOBILE | D25: 8939108640011149247 | E25: 3351333190 | F25: NO | G25: 46001 | H25: 46011 | I25: MNP EFFETTUATA | K25: OK | M25: OK | N25: SCADUTA | O25: SCADUTA
A26: YUDITH HERNANDEZ GARCIA | B26: 12/11/2025 | C26: ATTIVAZIONE SIM MNP - CONVERGENZA FISSO - MOBILE | D26: 8939108640011148850 | E26: 3318023757 | F26: NO | G26: 46003 | H26: 46013 | I26: MNP EFFETTUATA | J26: RINNOVO EFFETTUATO | M26: OK | N26: SCADUTA | O26: SCADUTA
A27: YUDITH HERNANDEZ GARCIA | B27: 13/11/2025 | C27: ATTIVAZIONE SIM MNP - MASSMARKET | D27: 8939108640011148611 | E27: 3486600553 | F27: NO | G27: 46004 | H27: 46014 | I27: MNP EFFETTUATA | J27: RINNOVO EFFETTUATO | M27: OK | N27: SCADUTA | O27: SCADUTA
A28: ANTONIO SACCO | B28: 13/11/2025 | C28: ATTIVAZIONE SIM MNP - CONVERGENZA FISSO - MOBILE | D28: 8939108640011149759 | E28: 3473641890 | F28: NO | G28: 46004 | H28: 46014 | I28: MNP EFFETTUATA | J28: RINNOVO EFFETTUATO | M28: OK | N28: SCADUTA | O28: SCADUTA
A29: ANTONIO SACCO | B29: 13/11/2025 | C29: ATTIVAZIONE SIM MNP - CONVERGENZA FISSO - MOBILE | D29: 8939108640012796731 | E29: 3489507337 | F29: NO | G29: 46004 | H29: 46014 | I29: MNP EFFETTUATA | J29: RINNOVO EFFETTUATO | M29: OK | N29: SCADUTA | O29: SCADUTA
A30: ANTONIO SACCO | B30: 14/11/2025 | C30: SIM SCONTATA - ATTIVAZIONE SIM MNP - CONV. FISSO - MOBILE | D30: 8939108660014738234 | E30: 3515135199 | F30: NO | G30: 46005 | H30: 46015 | I30: MNP EFFETTUATA | J30: RINNOVO EFFETTUATO | M30: OK | N30: SCADUTA | O30: SCADUTA
A31: KATIUSKA GEMMA DI GIOVANNI | B31: 15/11/2025 | C31: ATTIVAZIONE SIM MNP - TOKEN MVNO | D31: 8939108650001877590 | E31: 3203543632 | F31: SI | G31: 46006 | H31: 46016 | I31: MNP EFFETTUATA | J31: RINNOVO EFFETTUATO | M31: OK | N31: SCADUTA | O31: SCADUTA
A32: YUDITH HERNANDEZ GARCIA | B32: 16/11/2025 | C32: ATTIVAZIONE SIM MNP - MASSMARKET | D32: 8939108640006172105 | E32: 3248672055 | F32: NO | G32: 46006 | H32: 46017 | I32: MNP EFFETTUATA | J32: RINNOVO EFFETTUATO | M32: OK | N32: SCADUTA | O32: SCADUTA
A33: YUDITH HERNANDEZ GARCIA | B33: 16/11/2025 | C33: ATTIVAZIONE SIM MNP - CONVERGENZA FISSO - MOBILE | D33: 8939108640012796301 | E33: 3891773471 | F33: NO | G33: 46006 | H33: 46017 | I33: MNP EFFETTUATA | J33: RINNOVO EFFETTUATO | M33: OK | N33: SCADUTA | O33: SCADUTA
A34: YUDITH HERNANDEZ GARCIA | B34: 17/11/2025 | C34: ATTIVAZIONE SIM MNP - CONVERGENZA FISSO - MOBILE | D34: 8939108660014738440 | E34: 3331095959 | F34: NO | G34: 46006 | H34: 46018 | I34: MNP EFFETTUATA | J34: RINNOVO EFFETTUATO | M34: OK | N34: SCADUTA | O34: SCADUTA
A35: KATIUSKA GEMMA DI GIOVANNI | B35: 17/11/2025 | C35: ATTIVAZIONE SIM MNP - CONVERGENZA FISSO - MOBILE | D35: 8939108660014738598 | E35: 3407617881 | F35: NO | G35: 46006 | H35: 46018 | I35: MNP EFFETTUATA | J35: RINNOVO EFFETTUATO | M35: OK | N35: SCADUTA | O35: SCADUTA
A36: ANTONIO SACCO | B36: 18/11/2025 | C36: ATTIVAZIONE SIM MNP - MASSMARKET | D36: 8939108640011149452 | E36: 3883538096 | F36: NO | G36: 46006 | H36: 46019 | I36: MNP EFFETTUATA | K36: OK | M36: OK | N36: SCADUTA | O36: SCADUTA
A37: YUDITH HERNANDEZ GARCIA | B37: 19/11/2025 | C37: ATTIVAZIONE SIM MNP - MASSMARKET | D37: 8939108660014738333 | E37: 3500488272 | F37: NO | G37: 46006 | H37: 46020 | I37: MNP EFFETTUATA | K37: OK | M37: OK | N37: SCADUTA | O37: SCADUTA
A38: KATIUSKA GEMMA DI GIOVANNI | B38: 22/11/2025 | C38: SIM SCONTATA - ATTIVAZIONE SIM MNP - CONV. FISSO - MOBILE | D38: 8939108660014738630 | E38: 3801486294 | F38: SI | G38: 46006 | H38: 46023 | I38: MNP EFFETTUATA | K38: OK | M38: OK | N38: SCADUTA | O38: SCADUTA
A39: YUDITH HERNANDEZ GARCIA | B39: 22/11/2025 | C39: ATTIVAZIONE SIM MNP - CONVERGENZA FISSO - MOBILE | D39: 8939108660014738507 | E39: 3403138577 | F39: NO | G39: 46006 | H39: 46023 | I39: MNP EFFETTUATA | K39: OK | M39: OK | N39: SCADUTA | O39: SCADUTA
A40: KATIUSKA GEMMA DI GIOVANNI | B40: 23/11/2025 | C40: SIM SCONTATA - ATTIVAZIONE SIM MNP - CONV. FISSO - MOBILE | D40: 8939108660014738580 | E40: 335450972 | F40: NO | G40: 46011 | H40: 46024 | I40: IN ATTESA DI NORMALIZZAZIONE | K40: NON NORMALIZZABILE | M40: DA ELIMINARE | N40: SCADUTA | O40: SCADUTA
A41: KATIUSKA GEMMA DI GIOVANNI | B41: 23/11/2025 | C41: SIM SCONTATA - ATTIVAZIONE SIM MNP - CONV. FISSO - MOBILE | D41: 8939108660014738606 | E41: 3296031462 | F41: SI | G41: 46006 | H41: 46024 | I41: MNP EFFETTUATA | K41: OK | M41: OK | N41: SCADUTA | O41: SCADUTA
A42: ANTONIO SACCO | B42: 23/11/2025 | C42: ATTIVAZIONE SIM MNP - FASTWEB | D42: 8939080000125155683 | E42: 3382170418 | F42: NO | G42: 46006 | H42: 46024 | K42: OK | M42: OK | N42: SCADUTA | O42: SCADUTA
A43: YUDITH HERNANDEZ GARCIA | B43: 24/11/2025 | C43: ATTIVAZIONE SIM MNP - MASSMARKET | D43: 8939108660014738499 | E43: 3489218215 | F43: SI | G43: 46006 | H43: 46025 | I43: MNP EFFETTUATA | J43: RINNOVO EFFETTUATO | M43: OK | N43: SCADUTA | O43: SCADUTA
A44: KATIUSKA GEMMA DI GIOVANNI | B44: 24/11/2025 | C44: ATTIVAZIONE SIM MNP - MASSMARKET | D44: 8939108660014738077 | E44: 3383688360 | F44: NO | G44: 46006 | H44: 46025 | I44: MNP EFFETTUATA | J44: RINNOVO EFFETTUATO | M44: OK | N44: SCADUTA | O44: SCADUTA
...

Sheet FAMILY Vasto
A1: VASTO | B1: Column2 | C1: NEGOZIO DI RIFERIMENTO | D1: Column4 | E1: Column5 | F1: SELEZIONARE ESITO DAL MENÙ A TENDINA E | G1: Column7 | H1: Column8 | I1: Column9 | J1: Column10 | K1: Column11 | L1: Column12 | M1: Column13 | N1: Column14 | O1: Column15 | P1: Column16 | Q1: Column17
F2: AGGIUNGERE UN COMMENTO
A3: OPERATORE | B3: DATA | C3: TITOLO | D3: SIM | E3: TELEFONO | F3: DATA DI SCADENZA | G3: ESITO | H3: ESITO BO | I3: NOTE BO | J3: ESITO SUITE
A4: KADIMA GABRIEL TSHIMANGA | B4: 10/11/2025 | C4: ATTIVAZIONE CONVERGENZA FISSO - MOBILE | D4: 8939108640011140303 | E4: 3486949186 | F4: 46001 | G4: INSERITA IN FAMIGLIA | J4: OK | K4: SCADUTA | L4: SCADUTA | M4: NON SCADUTA | O4: TIPOLOGIA | Q4: INSERITA IN FAMIGLIA
A5: FILOMENA CHIAPPINI | B5: 10/11/2025 | C5: ATTIVAZIONE CONVERGENZA FISSO - MOBILE | D5: 8939108640012768144 | E5: 3342562021 | F5: 46001 | G5: INSERITA IN FAMIGLIA | J5: OK | K5: SCADUTA | L5: ATTIVITÀ SCADUTA | M5: INSERITA IN FAMIGLIA | O5: SCADUTA | Q5: IN ATTESA DI NORMALIZZAZIONE
A6: DONATO BOTTA | B6: 11/11/2025 | C6: ATTIVAZIONE CONVERGENZA FISSO - MOBILE | D6: 8939108640011140972 | E6: 3454613565 | F6: 46002 | G6: INSERITA IN FAMIGLIA | J6: OK | K6: SCADUTA | M6: IN ATTESA DI NORMALIZZAZIONE | O6: NON SCADUTA | Q6: NON NORMALIZZABILE
A7: KADIMA GABRIEL TSHIMANGA | B7: 13/11/2025 | C7: ATTIVAZIONE CONVERGENZA FISSO - MOBILE | D7: 8939108660014930310 | E7: 3479528752 | F7: 46004 | G7: INSERITA IN FAMIGLIA | J7: OK | K7: SCADUTA | M7: NON NORMALIZZABILE | Q7: MNP OUT
A8: FILOMENA CHIAPPINI | B8: 14/11/2025 | C8: ATTIVAZIONE CONVERGENZA FISSO - MOBILE | D8: 8939108630011216641 | E8: 3772991537 | F8: 46005 | G8: INSERITA IN FAMIGLIA | J8: OK | K8: SCADUTA | M8: MNP OUT
A9: FILOMENA CHIAPPINI | B9: 14/11/2025 | C9: ATTIVAZIONE CONVERGENZA FISSO - MOBILE | D9: 8939108640011140915 | E9: 3338486636 | F9: 46005 | G9: INSERITA IN FAMIGLIA | J9: OK | K9: SCADUTA
A10: FILOMENA CHIAPPINI | B10: 14/11/2025 | C10: ATTIVAZIONE CONVERGENZA FISSO - MOBILE | D10: 8939108660014938099 | E10: 3287820290 | F10: 46005 | G10: INSERITA IN FAMIGLIA | J10: OK | K10: SCADUTA
A11: FILOMENA CHIAPPINI | B11: 14/11/2025 | C11: ATTIVAZIONE CONVERGENZA FISSO - MOBILE | D11: 8939108640011140873 | E11: 3286485206 | F11: 46005 | G11: INSERITA IN FAMIGLIA | J11: OK | K11: SCADUTA
A12: FILOMENA CHIAPPINI | B12: 15/11/2025 | C12: ATTIVAZIONE CONVERGENZA FISSO - MOBILE | D12: 8939108630011217185 | E12: 3488941785 | F12: 46006 | G12: INSERITA IN FAMIGLIA | J12: OK | K12: SCADUTA
A13: FILOMENA CHIAPPINI | B13: 15/11/2025 | C13: ATTIVAZIONE CONVERGENZA FISSO - MOBILE | D13: 8939108660014930500 | E13: 3452197494 | F13: 46006 | G13: INSERITA IN FAMIGLIA | J13: OK | K13: SCADUTA
A14: FILOMENA CHIAPPINI | B14: 15/11/2025 | C14: ATTIVAZIONE CONVERGENZA FISSO - MOBILE | D14: 8939108660014938115 | E14: 3935785684 | F14: 46006 | G14: INSERITA IN FAMIGLIA | J14: OK | K14: SCADUTA
A15: FILOMENA CHIAPPINI | B15: 15/11/2025 | C15: ATTIVAZIONE CONVERGENZA FISSO - MOBILE | D15: 8939108660014937943 | E15: 3337162377 | F15: 46006 | G15: INSERITA IN FAMIGLIA | J15: OK | K15: SCADUTA
A16: FILOMENA CHIAPPINI | B16: 15/11/2025 | C16: ATTIVAZIONE CONVERGENZA FISSO - MOBILE | D16: 8939108660014930492 | E16: 3292915314 | F16: 46006 | G16: INSERITA IN FAMIGLIA | J16: OK | K16: SCADUTA
A17: KADIMA GABRIEL TSHIMANGA | B17: 22/11/2025 | C17: ATTIVAZIONE CONVERGENZA FISSO - MOBILE | D17: 8939108660014938032 | E17: 3490078709 | F17: 46006 | G17: INSERITA IN FAMIGLIA | J17: OK | K17: SCADUTA
A18: FILOMENA CHIAPPINI | B18: 28/11/2025 | C18: ATTIVAZIONE CONVERGENZA FISSO - MOBILE | D18: 8939108660014930393 | E18: 3801839185 | F18: 46006 | G18: INSERITA IN FAMIGLIA | J18: OK | K18: SCADUTA

Sheet MNP Vasto
